Traceback (most recent call last):
  File "/Users/dialidsantiago/Git/Plotly-Dash-Cookbook-Preview/.venv/lib/python3.11/site-packages/jupyter_cache/executors/utils.py", line 58, in single_nb_execution
    executenb(
  File "/Users/dialidsantiago/Git/Plotly-Dash-Cookbook-Preview/.venv/lib/python3.11/site-packages/nbclient/client.py", line 1314, in execute
    return NotebookClient(nb=nb, resources=resources, km=km, **kwargs).execute()
           ^^^^^^^^^^^^^^^^^^^^^^^^^^^^^^^^^^^^^^^^^^^^^^^^^^^^^^^^^^^^^^^^^^^^^
  File "/Users/dialidsantiago/Git/Plotly-Dash-Cookbook-Preview/.venv/lib/python3.11/site-packages/jupyter_core/utils/__init__.py", line 165, in wrapped
    return loop.run_until_complete(inner)
           ^^^^^^^^^^^^^^^^^^^^^^^^^^^^^^
  File "/Library/Frameworks/Python.framework/Versions/3.11/lib/python3.11/asyncio/base_events.py", line 653, in run_until_complete
    return future.result()
           ^^^^^^^^^^^^^^^
  File "/Users/dialidsantiago/Git/Plotly-Dash-Cookbook-Preview/.venv/lib/python3.11/site-packages/nbclient/client.py", line 709, in async_execute
    await self.async_execute_cell(
  File "/Users/dialidsantiago/Git/Plotly-Dash-Cookbook-Preview/.venv/lib/python3.11/site-packages/nbclient/client.py", line 1062, in async_execute_cell
    await self._check_raise_for_error(cell, cell_index, exec_reply)
  File "/Users/dialidsantiago/Git/Plotly-Dash-Cookbook-Preview/.venv/lib/python3.11/site-packages/nbclient/client.py", line 918, in _check_raise_for_error
    raise CellExecutionError.from_cell_and_msg(cell, exec_reply_content)
nbclient.exceptions.CellExecutionError: An error occurred while executing the following cell:
------------------
fig = px.scatter(df, x='x', y ='y',
                 title='Scatter + Fitted Polynomial')
fig.add_scatter(x=df.x, y =predicted, name="Fitted Polynomial")
fig.show()
------------------


[0;31m---------------------------------------------------------------------------[0m
[0;31mNameError[0m                                 Traceback (most recent call last)
Cell [0;32mIn[16], line 3[0m
[1;32m      1[0m fig [38;5;241m=[39m px[38;5;241m.[39mscatter(df, x[38;5;241m=[39m[38;5;124m'[39m[38;5;124mx[39m[38;5;124m'[39m, y [38;5;241m=[39m[38;5;124m'[39m[38;5;124my[39m[38;5;124m'[39m,
[1;32m      2[0m                  title[38;5;241m=[39m[38;5;124m'[39m[38;5;124mScatter + Fitted Polynomial[39m[38;5;124m'[39m)
[0;32m----> 3[0m fig[38;5;241m.[39madd_scatter(x[38;5;241m=[39mdf[38;5;241m.[39mx, y [38;5;241m=[39m[43mpredicted[49m, name[38;5;241m=[39m[38;5;124m"[39m[38;5;124mFitted Polynomial[39m[38;5;124m"[39m)
[1;32m      4[0m fig[38;5;241m.[39mshow()

[0;31mNameError[0m: name 'predicted' is not defined

